Workbook

Sheet Backlog
A1: Release | B1: Epic ID | C1: Epic | D1: Feature | E1: Story ID | F1: Story | G1: Acceptance criteria | H1: Role | I1: Estimate (person-days) | J1: Target week | K1: Priority | L1: Depends on | M1: Status | N1: As built (spec · note)
A2: R1 | B2: E1 | C2: Platform Foundation | D2: Infrastructure as Code | E2: S1 | F2: Terraform baseline: repo structure, S3+DynamoDB state, dev/prod env skeletons, networking for Aurora | G2: terraform apply creates empty env in a fresh account | H2: DevOps | I2: 2 | J2: 1 | K2: Must | M2: Delivered — P1 | N2: Spec 001 — Terraform, two env roots, S3 + DynamoDB state
A3: R1 | B3: E1 | C3: Platform Foundation | D3: CI pipeline | E3: S2 | F3: GitHub Actions CI: ruff, mypy, pytest+moto, Angular build, terraform validate/plan on PR | G3: All checks gate merges to main | H3: DevOps | I3: 2 | J3: 1 | K3: Must | L3: S1 | M3: Delivered — P1 | N3: Spec 001 — CI grew to 16 required checks
A4: R1 | B4: E1 | C4: Platform Foundation | D4: CD pipeline | E4: S3 | F4: CD with GitHub OIDC roles: auto-deploy dev on merge, gated prod deploy, Alembic migration step | G4: Merge to main reaches dev unattended; prod needs approval | H4: DevOps | I4: 2 | J4: 2 | K4: Must | L4: S2 | M4: Delivered — P1 | N4: Spec 001 — OIDC deploys; auto-deploy is opt-in (DEV_AUTO_DEPLOY), prod unused by decision
A5: R1 | B5: E1 | C5: Platform Foundation | D5: Database | E5: S4 | F5: Aurora Serverless v2 (PostgreSQL) + Alembic baseline schema (tenants, accounts, resources, rules, findings, owners, scans, audit) | G5: Migrations run in pipeline; ERD in repo | H5: BE1 | I5: 2 | J5: 1 | K5: Must | L5: S1 | M5: Delivered — P1 | N5: Spec 001 — Aurora Serverless v2, Alembic (17 migrations)
A6: R1 | B6: E1 | C6: Platform Foundation | D6: Identity | E6: S5 | F6: Cognito user pool, admin/operator/viewer groups, hosted UI, JWT authorizer on API Gateway | G6: Login works end-to-end; role claims in JWT | H6: DevOps | I6: 2 | J6: 2 | K6: Must | L6: S1 | M6: Delivered — P1 | N6: Spec 001 — Cognito, three groups, Lambda authorizer
A7: R1 | B7: E1 | C7: Platform Foundation | D7: API skeleton | E7: S6 | F7: FastAPI + Mangum on Lambda behind HTTP API; Powertools logging/tracing/metrics; health + error envelope | G7: GET /health 200 via CloudFront path; structured logs in CloudWatch | H7: BE1 | I7: 2 | J7: 1 | K7: Must | L7: S1 | M7: Delivered — P1 | N7: Spec 001 — FastAPI + Mangum, Powertools logging
A8: R1 | B8: E1 | C8: Platform Foundation | D8: Observability | E8: S7 | F8: CloudWatch dashboard + alarms (API 5xx, scan failures, DLQ depth) with email alerts | G8: Forced failure pages the team | H8: DevOps | I8: 1.5 | J8: 3 | K8: Should | L8: S3 | M8: Delivered — P2 | N8: Spec 001 — observability module, off by default
A9: R1 | B9: E2 | C9: Account Onboarding & Access | D9: Scanner role | E9: S8 | F9: Two auth modes (roles only): same-account local IAM role for the launch account + CloudFormation CloudPulseScannerRole template (ExternalId) for future cross-account. No access-key auth. | G9: Same-account scan works with zero AssumeRole; cross-account template deploys in <5 min and fails without ExternalId | H9: BE2 | I9: 2 | J9: 1 | K9: Must | M9: Delivered — P1 | N9: Spec 002 — same-account and cross-account modes; same-account grants fixed live (T063)
A10: R1 | B10: E2 | C10: Account Onboarding & Access | D10: Registration | E10: S9 | F10: Account registration API: add account (mode, role ARN, scan-region list, default us-east-1), verify via dry-run credential check + minimal describe | G10: Bad role/ExternalId/region rejected with a clear error; regions editable later | H10: BE2 | I10: 1.5 | J10: 1 | K10: Must | L10: S6,S8 | M10: Delivered — P1 | N10: Spec 002 — registration API with ExternalId; failure reason added (T062)
A11: R1 | B11: E2 | C11: Account Onboarding & Access | D11: Admin UI | E11: S10 | F11: Accounts admin page: list/add/verify accounts, scan status per account | G11: Operator onboards an account without touching AWS console (except stack deploy) | H11: FE | I11: 1.5 | J11: 2 | K11: Must | L11: S9 | M11: Delivered — P1 | N11: Spec 002 — accounts page
A12: R1 | B12: E3 | C12: Resource Discovery Engine | D12: Resource model | E12: S11 | F12: Normalized resource model (Pydantic) + provider connector interface (AWS first, Azure-shaped) | G12: Connector contract documented; AWS connector implements it | H12: BE1 | I12: 1.5 | J12: 1 | K12: Must | M12: Delivered — P1 | N12: Spec 002 — normalized model + Connector protocol
A13: R1 | B13: E3 | C13: Resource Discovery Engine | D13: Sweep | E13: S12 | F13: Tagging API sweep Lambda: paginated GetResources per region, ARN parsing to service/type | G13: All tagged resources of a test account land normalized | H13: BE2 | I13: 1.5 | J13: 1 | K13: Must | L13: S11 | M13: Delivered — P1 | N13: Spec 002 — Tagging API + Cloud Control sweep
A14: R1 | B14: E3 | C14: Resource Discovery Engine | D14: Enrichers | E14: S13 | F14: Enrichers: EC2 (state, type, launch), EBS (attachment), EIP (association) incl. untagged discovery via describes | G14: Untagged EC2/EBS/EIP appear in inventory | H14: BE2 | I14: 1.5 | J14: 2 | K14: Must | L14: S12 | M14: Delivered — P1 | N14: Spec 002 — EC2, EBS, EIP enrichers
A15: R1 | B15: E3 | C15: Resource Discovery Engine | D15: Enrichers | E15: S14 | F15: Enrichers: S3 (region, creation), RDS (engine, class), Lambda (runtime, last modified) | G15: Fields visible in resource detail | H15: BE2 | I15: 1.5 | J15: 2 | K15: Must | L15: S12 | M15: Delivered — P1 | N15: Spec 002 — S3, RDS, Lambda enrichers
A16: R1 | B16: E3 | C16: Resource Discovery Engine | D16: Orchestration | E16: S15 | F16: Step Functions scan workflow: Map fan-out per account x region x service-group (global services once per account), retries/backoff, concurrency caps; EventBridge daily schedule + on-demand API | G16: Daily scan + UI-triggered scan complete across all registered regions | H16: BE1 | I16: 2.5 | J16: 2 | K16: Must | L16: S12 | M16: Delivered — P1 | N16: Spec 002 — Step Functions, one unit per account × region
A17: R1 | B17: E3 | C17: Resource Discovery Engine | D17: Persistence | E17: S16 | F17: S3 raw snapshot writer + Postgres upsert with scan diffing (first_seen/last_seen/deleted_at; open/close findings hooks) | G17: Deleting a resource in AWS closes it in inventory next scan | H17: BE1 | I17: 2.5 | J17: 2 | K17: Must | L17: S15 | M17: Delivered — P1 | N17: Spec 002 — S3 snapshots + Postgres upsert with diffing
A18: R1 | B18: E3 | C18: Resource Discovery Engine | D18: History | E18: S17 | F18: Scan history recording + API (trigger, duration, counts, status) | G18: History page data matches CloudWatch reality | H18: BE2 | I18: 1 | J18: 3 | K18: Should | L18: S16 | M18: Delivered — P2 | N18: Spec 002/004 — scan history API and page
A19: R1 | B19: E4 | C19: Tag Compliance & Findings | D19: Rules | E19: S18 | F19: Rules-as-data: tag_rules table (case-insensitive keys, required set, allowed values) + admin CRUD API, seeded with the 4 mandatory tags | G19: Rule change applies on next scan without deploy | H19: BE1 | I19: 1.5 | J19: 2 | K19: Must | L19: S4 | M19: Delivered — P1 | N19: Spec 003 — rules as data, five seeded
A20: R1 | B20: E4 | C20: Tag Compliance & Findings | D20: SDA registry | E20: S18a | F20: SDA registry: register SDA (name, owner email, team, project_id/project_name tag values) via API + admin UI; resources attach to SDA at load time; unmatched -> 'No SDA' bucket | G20: Tagged resource shows its SDA; compliance score groups by SDA | H20: BE2 | I20: 1.5 | J20: 2 | K20: Must | L20: S16 | M20: Delivered — P1 | N20: Spec 003 — SDA registry
A21: R1 | B21: E4 | C21: Tag Compliance & Findings | D21: SDA registry UI | E21: S18b | F21: SDA admin page: CRUD + tag-value mapping editor + 'No SDA' triage list | G21: Registering an SDA reclassifies matching resources on next scan | H21: FE | I21: 1 | J21: 3 | K21: Must | L21: S18a | M21: Delivered — P2 | N21: Spec 003/004 — SDA page and “No SDA” triage
A22: R1 | B22: E4 | C22: Tag Compliance & Findings | D22: Validation | E22: S19 | F22: Validation worker: evaluate rules on parent resources, open/close/dedupe findings (missing, invalid, non-standard format) | G22: Finding auto-closes when tag fixed and re-scan runs | H22: BE1 | I22: 2.5 | J22: 2 | K22: Must | L22: S16,S18 | M22: Delivered — P1 | N22: Spec 003 — validation worker, findings lifecycle
A23: R1 | B23: E4 | C23: Tag Compliance & Findings | D23: Scoring | E23: S20 | F23: Compliance score per account/project + API (compliant parents / total parents) | G23: Score matches hand-count on test account | H23: BE2 | I23: 1 | J23: 3 | K23: Must | L23: S19 | M23: Delivered — P1 | N23: Spec 003 — compliance score per account and SDA
A24: R1 | B24: E5 | C24: Ownership Attribution | D24: CloudTrail | E24: S21 | F24: Ownership worker: 90-day LookupEvents for creator on Create*/Run* events; human principal detection (IAM user / SSO) | G24: Creator found for console-created test resources | H24: BE2 | I24: 2 | J24: 2 | K24: Must | L24: S16 | M24: Delivered — P1 | N24: Spec 003 — CloudTrail creator attribution; sweeps fixed live (T046)
... A37: R1 | B37: E7 | C37: Governance Dashboard (Angular) | D37: Hardening | E37: S33 | F37: E2E smoke tests (Playwright), empty/error states, deploy polish | G37: CI runs e2e against dev after deploy | H37: FE | I37: 1.5 | J37: 3 | K37: Should | L37: S30 | M37: Delivered — P2 | N37: Spec 004 — Playwright e2e, now run in CI
A38: R2 | B38: E8 | C38: Remediation Engine | D38: Policy | E38: S34 | F38: Policy evaluation: map finding class -> eligible action, auto vs approval-required rules-as-data | G38: Dry-run report lists intended actions per account | H38: BE1 | I38: 3 | J38: 4 | K38: Must | M38: Out of scope | N38: Remediation engine out of scope — no write role exists
A39: R2 | B39: E8 | C39: Remediation Engine | D39: Approvals | E39: S35 | F39: Approval workflow: queue, approve/reject API + UI, admin-only, batch approve | G39: Non-admin cannot approve; audit row per decision | H39: FE | I39: 3 | J39: 5 | K39: Must | L39: S34 | M39: Out of scope | N39: Remediation engine out of scope
A40: R2 | B40: E8 | C40: Remediation Engine | D40: Actions | E40: S36 | F40: Remediation actions via CloudPulseRemediatorRole: apply missing tags, correct invalid values (EC2, S3, RDS, Lambda, EBS) | G40: Tags applied in spoke; before/after in audit log | H40: BE2 | I40: 3 | J40: 5 | K40: Must | L40: S34 | M40: Out of scope | N40: Remediation engine out of scope
A41: R2 | B41: E8 | C41: Remediation Engine | D41: Safety | E41: S37 | F41: Dry-run default, per-account opt-in, rollback data (previous tag values), failure retry + DLQ | G41: Kill-switch disables all remediation in <1 min | H41: BE1 | I41: 2 | J41: 6 | K41: Must | L41: S36 | M41: Out of scope | N41: Remediation engine out of scope
A42: R2 | B42: E8 | C42: Remediation Engine | D42: Escalation | E42: S38 | F42: Escalation automation: unresolved after 4th interval -> escalate to project owner + report entry | G42: Escalation email cites full notification history | H42: BE2 | I42: 2 | J42: 6 | K42: Should | L42: S25 | M42: Partly delivered | N42: Day-4 escalation flag built (spec 005); no escalation email
A43: R2 | B43: E9 | C43: Cost Governance | D43: Spend | E43: S39 | F43: Cost Explorer integration: daily spend by project tag/account/service into Postgres (24h granularity) | G43: Spend matches CE console +/-1% | H43: BE1 | I43: 3 | J43: 4 | K43: Must | M43: Delivered — P1 | N43: Spec 005 — Cost Explorer daily spend
A44: R2 | B44: E9 | C44: Cost Governance | D44: Budgets | E44: S40 | F44: Auto-create AWS Budgets per project (80%/100% actual+forecast alerts) from project registry | G44: New project gets budget within a day | H44: BE2 | I44: 2.5 | J44: 5 | K44: Must | L44: S39 | M44: Delivered differently | N44: Spec 005 — budgets per SDA inside CloudPulse, not the AWS Budgets service
A45: R2 | B45: E9 | C45: Cost Governance | D45: Overruns | E45: S41 | F45: Overrun detection -> budget findings into the standard findings/notification pipeline | G45: Overrun triggers owner email like a tag finding | H45: BE2 | I45: 2 | J45: 6 | K45: Must | L45: S40 | M45: Delivered — P2 | N45: Spec 005 — overrun → finding in the same workbench
A46: R2 | B46: E9 | C46: Cost Governance | D46: Cost UI | E46: S42 | F46: Cost dashboard: spend by project/SDA/env, trend charts, budget vs actual, drill-down | G46: Drill from org total to single resource spend | H46: FE | I46: 4 | J46: 6 | K46: Must | L46: S39 | M46: Delivered — P1 | N46: Spec 005 — cost dashboard
A47: R2 | B47: E10 | C47: GenAI Insights (Bedrock) | D47: Digest | E47: S43 | F47: Bedrock Converse integration + nightly insight digest job (top findings, cost deltas, trends) -> dashboard card | G47: Digest cites real ARNs/numbers only (validated against DB) | H47: BE1 | I47: 3 | J47: 7 | K47: Must | L47: S39 | M47: Delivered — P1 | N47: Spec 006 — daily digest on Bedrock AgentCore + Nova 2 Lite, grounded; proven live (T144)
A48: R2 | B48: E10 | C48: GenAI Insights (Bedrock) | D48: Suggester | E48: S44 | F48: Remediation suggester: per finding class, action + blast-radius note, shown in approval UI | G48: Suggestions render in approval screen; humans decide | H48: BE2 | I48: 2.5 | J48: 7 | K48: Should | L48: S34 | M48: Delivered differently | N48: Spec 006 — one suggestion per finding (not per class), grounded; proven live
A49: R2 | B49: E10 | C49: GenAI Insights (Bedrock) | D49: Weekly email | E49: S45 | F49: Weekly digest email to admins (SES) from stored insights | G49: Unsubscribes honored; content matches dashboard | H49: BE2 | I49: 1.5 | J49: 8 | K49: Could | L49: S43 | M49: Out of scope | N49: Weekly digest email not built
A50: R2 | B50: E10 | C50: GenAI Insights (Bedrock) | D50: Guardrails | E50: S46 | F50: Prompt suite + eval harness (golden outputs), cost caps, Haiku/Sonnet routing, Bedrock budget alarm | G50: Regression eval runs in CI; monthly Bedrock cost alarm | H50: BE1 | I50: 2 | J50: 8 | K50: Should | L50: S43 | M50: Partly delivered | N50: Spec 006 — eval suite (16 cases) + per-run token cap; single model, no routing
A51: R2 | B51: E11 | C51: Unused Resources & IAM Hygiene | D51: Enrichers | E51: S47 | F51: Enrichers: EKS, DynamoDB, ELB, IAM (roles/users/keys inventory) | G51: New types visible in inventory with detail | H51: BE2 | I51: 3 | J51: 7 | K51: Must | L51: S12 | M51: Delivered — P2 | N51: Spec 002 — EKS, DynamoDB, ELBv2, IAM role enrichers; grants fixed live (T064)
A52: R2 | B52: E11 | C52: Unused Resources & IAM Hygiene | D52: Unused v1 | E52: S48 | F52: Unused detection: idle EC2 (CPU<5% 14d), unattached EBS, orphaned EIP, idle RDS -> findings with monthly savings estimate | G52: Savings estimate within 20% of CE numbers | H52: BE1 | I52: 4 | J52: 8 | K52: Must | L52: S39,S47 | M52: Out of scope | N52: Superseded by utilization (S54) and rightsizing (S52)
...

Sheet Summary
A1: CloudPulse AI — Backlog Summary
A3: Capacity vs load per release
A4: Release | B4: Weeks | C4: People | D4: Raw capacity (pd) | E4: Focus capacity (80%) | F4: Planned load (pd) | G4: Load vs RAW | H4: Load vs FOCUS
A5: R1 | B5: 3 | C5: 4 | D5: =B5*C5*5 | E5: =D5*0.8 | F5: =SUMIFS(Backlog!$I$2:$I$67,Backlog!$A$2:$A$67,A5) | G5: =F5/D5 | H5: =F5/E5
A6: R2 | B6: 5 | C6: 4 | D6: =B6*C6*5 | E6: =D6*0.8 | F6: =SUMIFS(Backlog!$I$2:$I$67,Backlog!$A$2:$A$67,A6) | G6: =F6/D6 | H6: =F6/E6
A7: R3 | B7: 6 | C7: 4 | D7: =B7*C7*5 | E7: =D7*0.8 | F7: =SUMIFS(Backlog!$I$2:$I$67,Backlog!$A$2:$A$67,A7) | G7: =F7/D7 | H7: =F7/E7
A8: Note: R1 runs above focus capacity by design — scope is frozen; overflow stories (marked 'Should') are the cut line.
A10: Load by epic
A11: Epic ID | B11: Epic | C11: Release(s) | D11: Stories | E11: Planned load (pd)
A12: E1 | B12: Platform Foundation | C12: R1 | D12: =COUNTIFS(Backlog!$B$2:$B$67,A12,Backlog!$C$2:$C$67,B12) | E12: =SUMIFS(Backlog!$I$2:$I$67,Backlog!$B$2:$B$67,A12,Backlog!$C$2:$C$67,B12)
A13: E2 | B13: Account Onboarding & Access | C13: R1 | D13: =COUNTIFS(Backlog!$B$2:$B$67,A13,Backlog!$C$2:$C$67,B13) | E13: =SUMIFS(Backlog!$I$2:$I$67,Backlog!$B$2:$B$67,A13,Backlog!$C$2:$C$67,B13)
A14: E3 | B14: Resource Discovery Engine | C14: R1 | D14: =COUNTIFS(Backlog!$B$2:$B$67,A14,Backlog!$C$2:$C$67,B14) | E14: =SUMIFS(Backlog!$I$2:$I$67,Backlog!$B$2:$B$67,A14,Backlog!$C$2:$C$67,B14)
A15: E4 | B15: Tag Compliance & Findings | C15: R1 | D15: =COUNTIFS(Backlog!$B$2:$B$67,A15,Backlog!$C$2:$C$67,B15) | E15: =SUMIFS(Backlog!$I$2:$I$67,Backlog!$B$2:$B$67,A15,Backlog!$C$2:$C$67,B15)
A16: E5 | B16: Ownership Attribution | C16: R1, R2 | D16: =COUNTIFS(Backlog!$B$2:$B$67,A16,Backlog!$C$2:$C$67,B16) | E16: =SUMIFS(Backlog!$I$2:$I$67,Backlog!$B$2:$B$67,A16,Backlog!$C$2:$C$67,B16)
A17: E6 | B17: Notification Engine | C17: R1, R2 | D17: =COUNTIFS(Backlog!$B$2:$B$67,A17,Backlog!$C$2:$C$67,B17) | E17: =SUMIFS(Backlog!$I$2:$I$67,Backlog!$B$2:$B$67,A17,Backlog!$C$2:$C$67,B17)
A18: E7 | B18: Governance Dashboard (Angular) | C18: R1, R2 | D18: =COUNTIFS(Backlog!$B$2:$B$67,A18,Backlog!$C$2:$C$67,B18) | E18: =SUMIFS(Backlog!$I$2:$I$67,Backlog!$B$2:$B$67,A18,Backlog!$C$2:$C$67,B18)
A19: E8 | B19: Remediation Engine | C19: R2 | D19: =COUNTIFS(Backlog!$B$2:$B$67,A19,Backlog!$C$2:$C$67,B19) | E19: =SUMIFS(Backlog!$I$2:$I$67,Backlog!$B$2:$B$67,A19,Backlog!$C$2:$C$67,B19)
A20: E9 | B20: Cost Governance | C20: R2 | D20: =COUNTIFS(Backlog!$B$2:$B$67,A20,Backlog!$C$2:$C$67,B20) | E20: =SUMIFS(Backlog!$I$2:$I$67,Backlog!$B$2:$B$67,A20,Backlog!$C$2:$C$67,B20)
A21: E10 | B21: GenAI Insights (Bedrock) | C21: R2 | D21: =COUNTIFS(Backlog!$B$2:$B$67,A21,Backlog!$C$2:$C$67,B21) | E21: =SUMIFS(Backlog!$I$2:$I$67,Backlog!$B$2:$B$67,A21,Backlog!$C$2:$C$67,B21)
A22: E11 | B22: Unused Resources & IAM Hygiene | C22: R2, R3 | D22: =COUNTIFS(Backlog!$B$2:$B$67,A22,Backlog!$C$2:$C$67,B22) | E22: =SUMIFS(Backlog!$I$2:$I$67,Backlog!$B$2:$B$67,A22,Backlog!$C$2:$C$67,B22)
A23: E16 | B23: R2 Hardening | C23: R2 | D23: =COUNTIFS(Backlog!$B$2:$B$67,A23,Backlog!$C$2:$C$67,B23) | E23: =SUMIFS(Backlog!$I$2:$I$67,Backlog!$B$2:$B$67,A23,Backlog!$C$2:$C$67,B23)
... A27: E15 | B27: SaaS & Multi-Cloud Readiness | C27: R3 | D27: =COUNTIFS(Backlog!$B$2:$B$67,A27,Backlog!$C$2:$C$67,B27) | E27: =SUMIFS(Backlog!$I$2:$I$67,Backlog!$B$2:$B$67,A27,Backlog!$C$2:$C$67,B27)
B28: TOTAL | D28: =SUM(D12:D27) | E28: =SUM(E12:E27)
A30: Load by role (all releases)
A31: Role | B31: Stories | C31: Planned load (pd)
A32: BE1 | B32: =COUNTIFS(Backlog!$H$2:$H$67,A32) | C32: =SUMIFS(Backlog!$I$2:$I$67,Backlog!$H$2:$H$67,A32)
A33: BE2 | B33: =COUNTIFS(Backlog!$H$2:$H$67,A33) | C33: =SUMIFS(Backlog!$I$2:$I$67,Backlog!$H$2:$H$67,A33)
A34: FE | B34: =COUNTIFS(Backlog!$H$2:$H$67,A34) | C34: =SUMIFS(Backlog!$I$2:$I$67,Backlog!$H$2:$H$67,A34)
A35: DevOps | B35: =COUNTIFS(Backlog!$H$2:$H$67,A35) | C35: =SUMIFS(Backlog!$I$2:$I$67,Backlog!$H$2:$H$67,A35)
A37: As built — story outcomes (October 2026)
A38: Status | B38: Stories
A39: Delivered — P1 | B39: =COUNTIF(Backlog!$M$2:$M$67,A39)
A40: Delivered — P2 | B40: =COUNTIF(Backlog!$M$2:$M$67,A40)
A41: Delivered differently | B41: =COUNTIF(Backlog!$M$2:$M$67,A41)
A42: Partly delivered | B42: =COUNTIF(Backlog!$M$2:$M$67,A42)
A43: Descoped | B43: =COUNTIF(Backlog!$M$2:$M$67,A43)
A44: Out of scope | B44: =COUNTIF(Backlog!$M$2:$M$67,A44)
A45: TOTAL | B45: =SUM(B39:B44)
A46: Built solo, spec-first, as six feature specs (481 tasks) rather than three releases by four people. The capacity and load figures above are the v1.0 plan, kept for comparison.
